Workbook

Sheet Summary
A1: Selong Bay School — 10-Year Summary
A2: Lombok, Indonesia | Ages 3–12 | Capacity grows to 150 students by Year 7 | Fees +5%/year
A4: Metric | B4: ="Year "&1&" ("&(Assumptions!$B$8+0)&")" -> Year 1 (2026) | C4: ="Year "&2&" ("&(Assumptions!$B$8+1)&")" -> Year 2 (2027) | D4: ="Year "&3&" ("&(Assumptions!$B$8+2)&")" -> Year 3 (2028) | E4: ="Year "&4&" ("&(Assumptions!$B$8+3)&")" -> Year 4 (2029) | F4: ="Year "&5&" ("&(Assumptions!$B$8+4)&")" -> Year 5 (2030) | G4: ="Year "&6&" ("&(Assumptions!$B$8+5)&")" -> Year 6 (2031) | H4: ="Year "&7&" ("&(Assumptions!$B$8+6)&")" -> Year 7 (2032) | I4: ="Year "&8&" ("&(Assumptions!$B$8+7)&")" -> Year 8 (2033) | J4: ="Year "&9&" ("&(Assumptions!$B$8+8)&")" -> Year 9 (2034) | K4: ="Year "&10&" ("&(Assumptions!$B$8+9)&")" -> Year 10 (2035)
A5: Enrollment — End of Year | B5: ='Enrollment & Revenue'!B5 -> 30 | C5: ='Enrollment & Revenue'!C5 -> 39.24 | D5: ='Enrollment & Revenue'!D5 -> 51.32592 | E5: ='Enrollment & Revenue'!E5 -> 67.134303 | F5: ='Enrollment & Revenue'!F5 -> 87.811669 | G5: ='Enrollment & Revenue'!G5 -> 114.85766 | H5: ='Enrollment & Revenue'!H5 -> 150 | I5: ='Enrollment & Revenue'!I5 -> 150 | ... K5: ='Enrollment & Revenue'!K5 -> 150
A6: Average Enrollment (used for revenue) | B6: ='Enrollment & Revenue'!B6 -> 21 | C6: ='Enrollment & Revenue'!C6 -> 34.62 | D6: ='Enrollment & Revenue'!D6 -> 45.28296 | E6: ='Enrollment & Revenue'!E6 -> 59.230112 | F6: ='Enrollment & Revenue'!F6 -> 77.472986 | G6: ='Enrollment & Revenue'!G6 -> 101.33467 | H6: ='Enrollment & Revenue'!H6 -> 132.42883 | I6: ='Enrollment & Revenue'!I6 -> 150 | ... K6: ='Enrollment & Revenue'!K6 -> 150
A7: Total Revenue | B7: ='10-Year P&L'!B8 -> 1479712500 | C7: ='10-Year P&L'!C8 -> 2.5613823e+09 | D7: ='10-Year P&L'!D8 -> 3.5178025e+09 | E7: ='10-Year P&L'!E8 -> 4.83135e+09 | F7: ='10-Year P&L'!F8 -> 6.635376e+09 | G7: ='10-Year P&L'!G8 -> 9.1130254e+09 | H7: ='10-Year P&L'!H8 -> 1.250479e+10 | I7: ='10-Year P&L'!I8 -> 1.4872172e+10 | ... K7: ='10-Year P&L'!K8 -> 1.639657e+10
A8: Total Operating Expenses | B8: ='10-Year P&L'!B19 -> 2329000000 | C8: ='10-Year P&L'!C19 -> 2460940000 | D8: ='10-Year P&L'!D19 -> 2600796400 | E8: ='10-Year P&L'!E19 -> 2749044184 | F8: ='10-Year P&L'!F19 -> 2.9061868e+09 | G8: ='10-Year P&L'!G19 -> 2.942758e+09 | H8: ='10-Year P&L'!H19 -> 3.1193235e+09 | I8: ='10-Year P&L'!I19 -> 3.3064829e+09 | ... K8: ='10-Year P&L'!K19 -> 3.7151642e+09
A9: EBIT | B9: ='10-Year P&L'!B21 -> -849287500 | C9: ='10-Year P&L'!C21 -> 1.0044234e+08 | D9: ='10-Year P&L'!D21 -> 9.170061e+08 | E9: ='10-Year P&L'!E21 -> 2.0823058e+09 | F9: ='10-Year P&L'!F21 -> 3.7291892e+09 | G9: ='10-Year P&L'!G21 -> 6.1702674e+09 | H9: ='10-Year P&L'!H21 -> 9.3854661e+09 | I9: ='10-Year P&L'!I21 -> 1.1565689e+10 | ... K9: ='10-Year P&L'!K21 -> 1.2681405e+10
A10: Net Income | B10: ='10-Year P&L'!B23 -> -849287500 | C10: ='10-Year P&L'!C23 -> 78345023 | D10: ='10-Year P&L'!D23 -> 7.1526476e+08 | E10: ='10-Year P&L'!E23 -> 1.6241985e+09 | F10: ='10-Year P&L'!F23 -> 2.9087676e+09 | G10: ='10-Year P&L'!G23 -> 4.8128086e+09 | H10: ='10-Year P&L'!H23 -> 7.3206635e+09 | I10: ='10-Year P&L'!I23 -> 9.0212375e+09 | ... K10: ='10-Year P&L'!K23 -> 9.8914962e+09
A11: Net Margin (%) | B11: ='10-Year P&L'!B24 -> -0.5739544 | C11: ='10-Year P&L'!C24 -> 0.030587008 | D11: ='10-Year P&L'!D24 -> 0.20332715 | E11: ='10-Year P&L'!E24 -> 0.33617902 | F11: ='10-Year P&L'!F24 -> 0.43837268 | G11: ='10-Year P&L'!G24 -> 0.52812412 | H11: ='10-Year P&L'!H24 -> 0.58542877 | I11: ='10-Year P&L'!I24 -> 0.60658507 | ... K11: ='10-Year P&L'!K24 -> 0.6032662
A13: Cumulative Net Income (Yr1–Yr10) | B13: =SUM(B10:K10) -> 4.4970003e+10
A14: Total Startup Capex (Year 0) | B14: =Assumptions!B57 -> 650000000

Sheet Assumptions
A1: Selong Bay School — Key Assumptions (10-Year Projection)
A2: School in Lombok, Indonesia | Ages 3–12 | All figures in Indonesian Rupiah (IDR)
A4: General
A5: School Name | B5: Selong Bay School
A6: Location | B6: Lombok, Indonesia
A7: Currency | B7: IDR
A8: Projection Start Year | B8: 2026
A9: Corporate Income Tax Rate | B9: 0.22 | C9: Indonesia standard corporate income tax rate.
A10: Annual Cost Inflation Rate (staffing & opex) | B10: 0.06 | C10: Illustrative assumption for planning purposes only — Selong Bay School management should confirm against local market data before relying on this model.
A11: Annual Tuition Fee Increase Rate | B11: 0.05 | C11: Provided by user: tuition and other student fees increase 5% per year.
A12: Post-Ramp Enrollment Growth Rate (Years 2–7) | B12: 0.308 | C12: Calibrated so enrollment grows from 30 students (end of Year 1) to the 150-student capacity by the end of Year 7, then holds at capacity through Year 10.
A14: Staffing
A15: Principal — Headcount | B15: 1
A16: Principal — Monthly Salary (IDR) | B16: 22000000 | C16: Provided by user.
A17: Expat Homeroom Supervisor — Headcount | B17: 1
A18: Expat Homeroom Supervisor — Monthly Salary (IDR) | B18: 40000000 | C18: Provided by user.
A19: Teachers — Headcount | B19: 5
A20: Teachers — Monthly Salary per Teacher (IDR) | B20: 8000000 | C20: Illustrative assumption for planning purposes only — Selong Bay School management should confirm against local market data before relying on this model.
A21: Support Staff (admin, cleaning, security) — Headcount | B21: 3 | C21: Illustrative assumption for planning purposes only — Selong Bay School management should confirm against local market data before relying on this model.
A22: Support Staff — Monthly Salary per Head (IDR) | B22: 3500000 | C22: Illustrative assumption for planning purposes only — Selong Bay School management should confirm against local market data before relying on this model.
A23: Employee Benefits / BPJS (% of salary, local staff) | B23: 0.1 | C23: Statutory social security & health insurance, employer portion — illustrative.
A24: Expat Work Permit (IMTA/KITAS) & Relocation Costs (IDR/year) | B24: 30000000 | C24: Illustrative annual cost of expat visa/work permit sponsorship, renewal, and related admin for the homeroom supervisor.
A26: Enrollment & Tuition (Year 1 base)
A27: Starting Enrollment — Month 0 (students, ages 3–12) | B27: 12 | C27: Provided by user.
A28: Year 1 Ending Enrollment — Month 12 | B28: 30 | C28: Provided by user: ramps from 12 to 21 within the first 6 months, then to 30 over the next 6 months. This model uses the straight-line average (21 students) for Year 1 revenue.
A29: School Capacity (max students) | B29: 150 | C29: Provided by user: capacity reaches 150 students by Year 7.
A30: Average Annual Tuition Fee per Student (IDR, blended reference only) | B30: 95000000 | C30: Superseded by the per-level fee schedule below; retained for reference.
A31: Annual Registration/Enrollment Fee per Student (IDR) | B31: 4000000 | C31: Illustrative assumption for planning purposes only — Selong Bay School management should confirm against local market data before relying on this model.
A32: Annual Uniforms, Books & Materials Fee per Student (IDR) | B32: 2000000 | C32: Illustrative assumption for planning purposes only — Selong Bay School management should confirm against local market data before relying on this model.
A34: Tuition Fee Schedule (Per Term, Year 1 base)
A35: Preschool (ages 2–5) — Per Term Fee (IDR) | B35: 10000000 | C35: Provided by user pricing guide.
A36: Primary (ages 6–12) — Per Term Fee (IDR) | B36: 23750000 | C36: Provided by user pricing guide.
A37: Secondary (ages 13–18) — Per Term Fee (IDR) | B37: 27000000 | C37: Provided by user pricing guide.
A38: Terms per Year | B38: 3 | C38: Illustrative assumption for planning purposes only — Selong Bay School management should confirm against local market data before relying on this model.
A39: Enrollment Mix — Preschool (%) | B39: 0.2 | C39: Illustrative assumption for planning purposes only — Selong Bay School management should confirm against local market data before relying on this model.
A40: Enrollment Mix — Primary (%) | B40: 0.65 | C40: Most students are in the Primary group, per user instruction.
A41: Enrollment Mix — Secondary (%) | B41: 0.15 | C41: Illustrative assumption for planning purposes only — Selong Bay School management should confirm against local market data before relying on this model.
A42: Check: Level Mix Sums to 100% | B42: =B39+B40+B41 -> 1
A44: Operating Costs (Monthly, Year 1 base)
A45: Facility Lease (IDR/month, payable to Lee) | B45: 40000000 | C45: Provided by user.
...

Sheet Staffing
A1: Selong Bay School — Staffing Cost Plan (10-Year)
A3: Role | B3: Headcount | C3: Monthly Salary (per head, IDR) | D3: Benefits % | E3: Monthly Cost (per head, incl. benefits) | F3: Monthly Total Cost (IDR) | G3: Year 1 Annual Cost | H3: Year 2 Annual Cost | I3: Year 3 Annual Cost | J3: Year 4 Annual Cost | K3: Year 5 Annual Cost | L3: Year 6 Annual Cost | M3: Year 7 Annual Cost | N3: Year 8 Annual Cost | O3: Year 9 Annual Cost | P3: Year 10 Annual Cost
A4: Principal | B4: =Assumptions!B15 -> 1 | C4: =Assumptions!B16 -> 22000000 | D4: =Assumptions!$B$23 -> 0.1 | E4: =C4*(1+D4) -> 24200000 | F4: =E4*B4 -> 24200000 | G4: =F4*12 -> 290400000 | H4: =G4*(1+Assumptions!$B$10) -> 307824000 | I4: =H4*(1+Assumptions!$B$10) -> 326293440 | J4: =I4*(1+Assumptions!$B$10) -> 3.4587105e+08 | K4: =J4*(1+Assumptions!$B$10) -> 3.6662331e+08 | L4: =K4*(1+Assumptions!$B$10) -> 3.8862071e+08 | M4: =L4*(1+Assumptions!$B$10) -> 4.1193795e+08 | N4: =M4*(1+Assumptions!$B$10) -> 4.3665423e+08 | O4: =N4*(1+Assumptions!$B$10) -> 4.6285348e+08 | P4: =O4*(1+Assumptions!$B$10) -> 4.9062469e+08
A5: Expat Homeroom Supervisor | B5: =Assumptions!B17 -> 1 | C5: =Assumptions!B18 -> 40000000 | D5: 0 | E5: =C5*(1+D5) -> 40000000 | F5: =E5*B5 -> 40000000 | G5: =F5*12 -> 480000000 | H5: =G5*(1+Assumptions!$B$10) -> 508800000 | I5: =H5*(1+Assumptions!$B$10) -> 539328000 | J5: =I5*(1+Assumptions!$B$10) -> 571687680 | K5: =J5*(1+Assumptions!$B$10) -> 6.0598894e+08 | L5: =K5*(1+Assumptions!$B$10) -> 6.4234828e+08 | M5: =L5*(1+Assumptions!$B$10) -> 6.8088917e+08 | N5: =M5*(1+Assumptions!$B$10) -> 7.2174252e+08 | O5: =N5*(1+Assumptions!$B$10) -> 7.6504708e+08 | P5: =O5*(1+Assumptions!$B$10) -> 8.109499e+08
A6: Teachers | B6: =Assumptions!B19 -> 5 | C6: =Assumptions!B20 -> 8000000 | D6: =Assumptions!$B$23 -> 0.1 | E6: =C6*(1+D6) -> 8800000 | F6: =E6*B6 -> 44000000 | G6: =F6*12 -> 528000000 | H6: =G6*(1+Assumptions!$B$10) -> 559680000 | I6: =H6*(1+Assumptions!$B$10) -> 593260800 | J6: =I6*(1+Assumptions!$B$10) -> 628856448 | K6: =J6*(1+Assumptions!$B$10) -> 6.6658783e+08 | L6: =K6*(1+Assumptions!$B$10) -> 7.065831e+08 | M6: =L6*(1+Assumptions!$B$10) -> 7.4897809e+08 | N6: =M6*(1+Assumptions!$B$10) -> 7.9391678e+08 | O6: =N6*(1+Assumptions!$B$10) -> 8.4155178e+08 | P6: =O6*(1+Assumptions!$B$10) -> 8.9204489e+08
A7: Support Staff (admin/cleaning/security) | B7: =Assumptions!B21 -> 3 | C7: =Assumptions!B22 -> 3500000 | D7: =Assumptions!$B$23 -> 0.1 | E7: =C7*(1+D7) -> 3850000 | F7: =E7*B7 -> 11550000 | G7: =F7*12 -> 138600000 | H7: =G7*(1+Assumptions!$B$10) -> 146916000 | I7: =H7*(1+Assumptions!$B$10) -> 155730960 | J7: =I7*(1+Assumptions!$B$10) -> 1.6507482e+08 | K7: =J7*(1+Assumptions!$B$10) -> 1.7497931e+08 | L7: =K7*(1+Assumptions!$B$10) -> 1.8547807e+08 | M7: =L7*(1+Assumptions!$B$10) -> 1.9660675e+08 | N7: =M7*(1+Assumptions!$B$10) -> 2.0840315e+08 | O7: =N7*(1+Assumptions!$B$10) -> 2.2090734e+08 | P7: =O7*(1+Assumptions!$B$10) -> 2.3416178e+08
A8: Expat Work Permit (IMTA/KITAS) & Related Costs | G8: =Assumptions!$B$24 -> 30000000 | H8: =G8*(1+Assumptions!$B$10) -> 31800000 | I8: =H8*(1+Assumptions!$B$10) -> 33708000 | J8: =I8*(1+Assumptions!$B$10) -> 35730480 | K8: =J8*(1+Assumptions!$B$10) -> 37874309 | L8: =K8*(1+Assumptions!$B$10) -> 40146767 | M8: =L8*(1+Assumptions!$B$10) -> 42555573 | N8: =M8*(1+Assumptions!$B$10) -> 45108908 | O8: =N8*(1+Assumptions!$B$10) -> 47815442 | P8: =O8*(1+Assumptions!$B$10) -> 50684369
A9: Total Staffing Cost | C9: =SUM(C4:C8) -> 73500000 | E9: =SUM(E4:E8) -> 76850000 | F9: =SUM(F4:F8) -> 119750000 | G9: =SUM(G4:G8) -> 1467000000 | H9: =SUM(H4:H8) -> 1555020000 | I9: =SUM(I4:I8) -> 1648321200 | J9: =SUM(J4:J8) -> 1747220472 | K9: =SUM(K4:K8) -> 1.8520537e+09 | L9: =SUM(L4:L8) -> 1.9631769e+09 | ... P9: =SUM(P4:P8) -> 2.4784656e+09

Sheet Enrollment & Revenue
A1: Selong Bay School — Enrollment & Revenue Build (10-Year)
A3: Metric | B3: ="Year "&1&" ("&(Assumptions!$B$8+0)&")" -> Year 1 (2026) | C3: ="Year "&2&" ("&(Assumptions!$B$8+1)&")" -> Year 2 (2027) | D3: ="Year "&3&" ("&(Assumptions!$B$8+2)&")" -> Year 3 (2028) | E3: ="Year "&4&" ("&(Assumptions!$B$8+3)&")" -> Year 4 (2029) | F3: ="Year "&5&" ("&(Assumptions!$B$8+4)&")" -> Year 5 (2030) | G3: ="Year "&6&" ("&(Assumptions!$B$8+5)&")" -> Year 6 (2031) | H3: ="Year "&7&" ("&(Assumptions!$B$8+6)&")" -> Year 7 (2032) | I3: ="Year "&8&" ("&(Assumptions!$B$8+7)&")" -> Year 8 (2033) | J3: ="Year "&9&" ("&(Assumptions!$B$8+8)&")" -> Year 9 (2034) | K3: ="Year "&10&" ("&(Assumptions!$B$8+9)&")" -> Year 10 (2035)
A4: Enrollment — Start of Year | B4: =Assumptions!$B$27 -> 12 | C4: =B5 -> 30 | D4: =C5 -> 39.24 | E4: =D5 -> 51.32592 | F4: =E5 -> 67.134303 | G4: =F5 -> 87.811669 | H4: =G5 -> 114.85766 | I4: =H5 -> 150 | J4: =I5 -> 150 | K4: =J5 -> 150
A5: Enrollment — End of Year (capped at capacity) | B5: =Assumptions!$B$28 -> 30 | C5: =MIN(C4*(1+Assumptions!$B$12),Assumptions!$B$29) -> 39.24 | D5: =MIN(D4*(1+Assumptions!$B$12),Assumptions!$B$29) -> 51.32592 | E5: =MIN(E4*(1+Assumptions!$B$12),Assumptions!$B$29) -> 67.134303 | F5: =MIN(F4*(1+Assumptions!$B$12),Assumptions!$B$29) -> 87.811669 | G5: =MIN(G4*(1+Assumptions!$B$12),Assumptions!$B$29) -> 114.85766 | H5: =MIN(H4*(1+Assumptions!$B$12),Assumptions!$B$29) -> 150 | I5: =MIN(I4*(1+Assumptions!$B$12),Assumptions!$B$29) -> 150 | J5: =MIN(J4*(1+Assumptions!$B$12),Assumptions!$B$29) -> 150 | K5: =MIN(K4*(1+Assumptions!$B$12),Assumptions!$B$29) -> 150
A6: Average Enrollment (used for revenue) | B6: =(B4+B5)/2 -> 21 | C6: =(C4+C5)/2 -> 34.62 | D6: =(D4+D5)/2 -> 45.28296 | E6: =(E4+E5)/2 -> 59.230112 | F6: =(F4+F5)/2 -> 77.472986 | G6: =(G4+G5)/2 -> 101.33467 | H6: =(H4+H5)/2 -> 132.42883 | I6: =(I4+I5)/2 -> 150 | ... K6: =(K4+K5)/2 -> 150
A7: School Capacity | B7: =Assumptions!$B$29 -> 150 | C7: =Assumptions!$B$29 -> 150 | D7: =Assumptions!$B$29 -> 150 | E7: =Assumptions!$B$29 -> 150 | F7: =Assumptions!$B$29 -> 150 | G7: =Assumptions!$B$29 -> 150 | H7: =Assumptions!$B$29 -> 150 | I7: =Assumptions!$B$29 -> 150 | ... K7: =Assumptions!$B$29 -> 150
A8: Capacity Utilization at Year-End (%) | B8: =B5/B7 -> 0.2 | C8: =C5/C7 -> 0.2616 | D8: =D5/D7 -> 0.3421728 | E8: =E5/E7 -> 0.44756202 | F8: =F5/F7 -> 0.58541113 | G8: =G5/G7 -> 0.76571775 | H8: =H5/H7 -> 1 | I8: =I5/I7 -> 1 | ... K8: =K5/K7 -> 1
A9: Preschool Students (avg, 20% of mix) | B9: =B6*Assumptions!$B$39 -> 4.2 | C9: =C6*Assumptions!$B$39 -> 6.924 | D9: =D6*Assumptions!$B$39 -> 9.056592 | E9: =E6*Assumptions!$B$39 -> 11.846022 | F9: =F6*Assumptions!$B$39 -> 15.494597 | G9: =G6*Assumptions!$B$39 -> 20.266933 | H9: =H6*Assumptions!$B$39 -> 26.485766 | I9: =I6*Assumptions!$B$39 -> 30 | ... K9: =K6*Assumptions!$B$39 -> 30
A10: Primary Students (avg, 65% of mix) | B10: =B6*Assumptions!$B$40 -> 13.65 | C10: =C6*Assumptions!$B$40 -> 22.503 | D10: =D6*Assumptions!$B$40 -> 29.433924 | E10: =E6*Assumptions!$B$40 -> 38.499573 | F10: =F6*Assumptions!$B$40 -> 50.357441 | G10: =G6*Assumptions!$B$40 -> 65.867533 | H10: =H6*Assumptions!$B$40 -> 86.07874 | I10: =I6*Assumptions!$B$40 -> 97.5 | ... K10: =K6*Assumptions!$B$40 -> 97.5
A11: Secondary Students (avg, 15% of mix) | B11: =B6*Assumptions!$B$41 -> 3.15 | C11: =C6*Assumptions!$B$41 -> 5.193 | D11: =D6*Assumptions!$B$41 -> 6.792444 | E11: =E6*Assumptions!$B$41 -> 8.8845168 | F11: =F6*Assumptions!$B$41 -> 11.620948 | G11: =G6*Assumptions!$B$41 -> 15.2002 | H11: =H6*Assumptions!$B$41 -> 19.864325 | I11: =I6*Assumptions!$B$41 -> 22.5 | ... K11: =K6*Assumptions!$B$41 -> 22.5
A12: Preschool — Annual Fee per Student (IDR) | B12: =Assumptions!$B$35*Assumptions!$B$38 -> 30000000 | C12: =B12*(1+Assumptions!$B$11) -> 31500000 | D12: =C12*(1+Assumptions!$B$11) -> 33075000 | E12: =D12*(1+Assumptions!$B$11) -> 34728750 | F12: =E12*(1+Assumptions!$B$11) -> 36465188 | G12: =F12*(1+Assumptions!$B$11) -> 38288447 | H12: =G12*(1+Assumptions!$B$11) -> 40202869 | I12: =H12*(1+Assumptions!$B$11) -> 42213013 | J12: =I12*(1+Assumptions!$B$11) -> 44323663 | K12: =J12*(1+Assumptions!$B$11) -> 46539846
A13: Primary — Annual Fee per Student (IDR) | B13: =Assumptions!$B$36*Assumptions!$B$38 -> 71250000 | C13: =B13*(1+Assumptions!$B$11) -> 74812500 | D13: =C13*(1+Assumptions!$B$11) -> 78553125 | E13: =D13*(1+Assumptions!$B$11) -> 82480781 | F13: =E13*(1+Assumptions!$B$11) -> 86604820 | G13: =F13*(1+Assumptions!$B$11) -> 90935061 | H13: =G13*(1+Assumptions!$B$11) -> 95481814 | I13: =H13*(1+Assumptions!$B$11) -> 1.0025591e+08 | J13: =I13*(1+Assumptions!$B$11) -> 1.052687e+08 | K13: =J13*(1+Assumptions!$B$11) -> 1.1053214e+08
A14: Secondary — Annual Fee per Student (IDR) | B14: =Assumptions!$B$37*Assumptions!$B$38 -> 81000000 | C14: =B14*(1+Assumptions!$B$11) -> 85050000 | D14: =C14*(1+Assumptions!$B$11) -> 89302500 | E14: =D14*(1+Assumptions!$B$11) -> 93767625 | F14: =E14*(1+Assumptions!$B$11) -> 98456006 | G14: =F14*(1+Assumptions!$B$11) -> 1.0337881e+08 | H14: =G14*(1+Assumptions!$B$11) -> 1.0854775e+08 | I14: =H14*(1+Assumptions!$B$11) -> 1.1397513e+08 | J14: =I14*(1+Assumptions!$B$11) -> 1.1967389e+08 | K14: =J14*(1+Assumptions!$B$11) -> 1.2565759e+08
A15: Tuition Revenue (IDR) | B15: =B9*B12+B10*B13+B11*B14 -> 1353712500 | C15: =C9*C12+C10*C13+C11*C14 -> 2.3432763e+09 | D15: =D9*D12+D10*D13+D11*D14 -> 3.2182557e+09 | E15: =E9*E12+E10*E13+E11*E14 -> 4.4199524e+09 | F15: =F9*F12+F10*F13+F11*F14 -> 6.0703626e+09 | G15: =G9*G12+G10*G13+G11*G14 -> 8.337036e+09 | H15: =H9*H12+H10*H13+H11*H14 -> 1.1439986e+10 | I15: =I9*I12+I10*I13+I11*I14 -> 1.3605782e+10 | ... K15: =K9*K12+K10*K13+K11*K14 -> 1.5000374e+10
A16: Registration Fee per Student (IDR) | B16: =Assumptions!$B$31 -> 4000000 | C16: =B16*(1+Assumptions!$B$11) -> 4200000 | D16: =C16*(1+Assumptions!$B$11) -> 4410000 | E16: =D16*(1+Assumptions!$B$11) -> 4630500 | F16: =E16*(1+Assumptions!$B$11) -> 4862025 | G16: =F16*(1+Assumptions!$B$11) -> 5105126.2 | H16: =G16*(1+Assumptions!$B$11) -> 5360382.6 | I16: =H16*(1+Assumptions!$B$11) -> 5628401.7 | J16: =I16*(1+Assumptions!$B$11) -> 5909821.8 | K16: =J16*(1+Assumptions!$B$11) -> 6205312.9
A17: Registration Fee Revenue (IDR) | B17: =B6*B16 -> 84000000 | C17: =C6*C16 -> 145404000 | D17: =D6*D16 -> 1.9969785e+08 | E17: =E6*E16 -> 2.7426503e+08 | F17: =F6*F16 -> 3.766756e+08 | G17: =G6*G16 -> 5.1732626e+08 | H17: =H6*H16 -> 7.098692e+08 | I17: =I6*I16 -> 8.4426025e+08 | ... K17: =K6*K16 -> 9.3079693e+08
A18: Uniforms/Books/Materials Fee per Student (IDR) | B18: =Assumptions!$B$32 -> 2000000 | C18: =B18*(1+Assumptions!$B$11) -> 2100000 | D18: =C18*(1+Assumptions!$B$11) -> 2205000 | E18: =D18*(1+Assumptions!$B$11) -> 2315250 | F18: =E18*(1+Assumptions!$B$11) -> 2431012.5 | G18: =F18*(1+Assumptions!$B$11) -> 2552563.1 | H18: =G18*(1+Assumptions!$B$11) -> 2680191.3 | I18: =H18*(1+Assumptions!$B$11) -> 2814200.8 | J18: =I18*(1+Assumptions!$B$11) -> 2954910.9 | K18: =J18*(1+Assumptions!$B$11) -> 3102656.4
A19: Uniforms/Books/Materials Revenue (IDR) | B19: =B6*B18 -> 42000000 | C19: =C6*C18 -> 72702000 | D19: =D6*D18 -> 99848927 | E19: =E6*E18 -> 1.3713252e+08 | F19: =F6*F18 -> 1.883378e+08 | G19: =G6*G18 -> 2.5866313e+08 | H19: =H6*H18 -> 3.549346e+08 | I19: =I6*I18 -> 4.2213013e+08 | ... K19: =K6*K18 -> 4.6539846e+08
A20: Total Revenue (IDR) | B20: =B15+B17+B19 -> 1479712500 | C20: =C15+C17+C19 -> 2.5613823e+09 | D20: =D15+D17+D19 -> 3.5178025e+09 | E20: =E15+E17+E19 -> 4.83135e+09 | F20: =F15+F17+F19 -> 6.635376e+09 | G20: =G15+G17+G19 -> 9.1130254e+09 | H20: =H15+H17+H19 -> 1.250479e+10 | I20: =I15+I17+I19 -> 1.4872172e+10 | ... K20: =K15+K17+K19 -> 1.639657e+10

Sheet 10-Year P&L
A1: Selong Bay School — 10-Year Income Statement
A2: All figures in Indonesian Rupiah (IDR)
A3: Line Item | B3: ="Year "&1&" ("&(Assumptions!$B$8+0)&")" -> Year 1 (2026) | C3: ="Year "&2&" ("&(Assumptions!$B$8+1)&")" -> Year 2 (2027) | D3: ="Year "&3&" ("&(Assumptions!$B$8+2)&")" -> Year 3 (2028) | E3: ="Year "&4&" ("&(Assumptions!$B$8+3)&")" -> Year 4 (2029) | F3: ="Year "&5&" ("&(Assumptions!$B$8+4)&")" -> Year 5 (2030) | G3: ="Year "&6&" ("&(Assumptions!$B$8+5)&")" -> Year 6 (2031) | H3: ="Year "&7&" ("&(Assumptions!$B$8+6)&")" -> Year 7 (2032) | I3: ="Year "&8&" ("&(Assumptions!$B$8+7)&")" -> Year 8 (2033) | J3: ="Year "&9&" ("&(Assumptions!$B$8+8)&")" -> Year 9 (2034) | K3: ="Year "&10&" ("&(Assumptions!$B$8+9)&")" -> Year 10 (2035)
A4: Revenue
A5: Tuition Revenue | B5: ='Enrollment & Revenue'!B15 -> 1353712500 | C5: ='Enrollment & Revenue'!C15 -> 2.3432763e+09 | D5: ='Enrollment & Revenue'!D15 -> 3.2182557e+09 | E5: ='Enrollment & Revenue'!E15 -> 4.4199524e+09 | F5: ='Enrollment & Revenue'!F15 -> 6.0703626e+09 | G5: ='Enrollment & Revenue'!G15 -> 8.337036e+09 | H5: ='Enrollment & Revenue'!H15 -> 1.1439986e+10 | I5: ='Enrollment & Revenue'!I15 -> 1.3605782e+10 | ... K5: ='Enrollment & Revenue'!K15 -> 1.5000374e+10
A6: Registration Fee Revenue | B6: ='Enrollment & Revenue'!B17 -> 84000000 | C6: ='Enrollment & Revenue'!C17 -> 145404000 | D6: ='Enrollment & Revenue'!D17 -> 1.9969785e+08 | E6: ='Enrollment & Revenue'!E17 -> 2.7426503e+08 | F6: ='Enrollment & Revenue'!F17 -> 3.766756e+08 | G6: ='Enrollment & Revenue'!G17 -> 5.1732626e+08 | H6: ='Enrollment & Revenue'!H17 -> 7.098692e+08 | I6: ='Enrollment & Revenue'!I17 -> 8.4426025e+08 | ... K6: ='Enrollment & Revenue'!K17 -> 9.3079693e+08
A7: Uniforms/Books/Materials Revenue | B7: ='Enrollment & Revenue'!B19 -> 42000000 | C7: ='Enrollment & Revenue'!C19 -> 72702000 | D7: ='Enrollment & Revenue'!D19 -> 99848927 | E7: ='Enrollment & Revenue'!E19 -> 1.3713252e+08 | F7: ='Enrollment & Revenue'!F19 -> 1.883378e+08 | G7: ='Enrollment & Revenue'!G19 -> 2.5866313e+08 | H7: ='Enrollment & Revenue'!H19 -> 3.549346e+08 | I7: ='Enrollment & Revenue'!I19 -> 4.2213013e+08 | ... K7: ='Enrollment & Revenue'!K19 -> 4.6539846e+08
A8: Total Revenue | B8: =B5+B6+B7 -> 1479712500 | C8: =C5+C6+C7 -> 2.5613823e+09 | D8: =D5+D6+D7 -> 3.5178025e+09 | E8: =E5+E6+E7 -> 4.83135e+09 | F8: =F5+F6+F7 -> 6.635376e+09 | G8: =G5+G6+G7 -> 9.1130254e+09 | H8: =H5+H6+H7 -> 1.250479e+10 | I8: =I5+I6+I7 -> 1.4872172e+10 | ... K8: =K5+K6+K7 -> 1.639657e+10
A10: Operating Expenses
A11: Staffing Costs (incl. benefits & expat permit) | B11: =Staffing!G$9 -> 1467000000 | C11: =Staffing!H$9 -> 1555020000 | D11: =Staffing!I$9 -> 1648321200 | E11: =Staffing!J$9 -> 1747220472 | F11: =Staffing!K$9 -> 1.8520537e+09 | G11: =Staffing!L$9 -> 1.9631769e+09 | H11: =Staffing!M$9 -> 2.0809675e+09 | I11: =Staffing!N$9 -> 2.2058256e+09 | ... K11: =Staffing!P$9 -> 2.4784656e+09
A12: Facility Lease (payable to Lee) | B12: =Assumptions!$B$45*12 -> 480000000 | C12: =B12*(1+Assumptions!$B$10) -> 508800000 | D12: =C12*(1+Assumptions!$B$10) -> 539328000 | E12: =D12*(1+Assumptions!$B$10) -> 571687680 | F12: =E12*(1+Assumptions!$B$10) -> 6.0598894e+08 | G12: =F12*(1+Assumptions!$B$10) -> 6.4234828e+08 | H12: =G12*(1+Assumptions!$B$10) -> 6.8088917e+08 | I12: =H12*(1+Assumptions!$B$10) -> 7.2174252e+08 | J12: =I12*(1+Assumptions!$B$10) -> 7.6504708e+08 | K12: =J12*(1+Assumptions!$B$10) -> 8.109499e+08
A13: Utilities | B13: =Assumptions!$B$46*12 -> 72000000 | C13: =B13*(1+Assumptions!$B$10) -> 76320000 | D13: =C13*(1+Assumptions!$B$10) -> 80899200 | E13: =D13*(1+Assumptions!$B$10) -> 85753152 | F13: =E13*(1+Assumptions!$B$10) -> 90898341 | G13: =F13*(1+Assumptions!$B$10) -> 96352242 | H13: =G13*(1+Assumptions!$B$10) -> 1.0213338e+08 | I13: =H13*(1+Assumptions!$B$10) -> 1.0826138e+08 | J13: =I13*(1+Assumptions!$B$10) -> 1.1475706e+08 | K13: =J13*(1+Assumptions!$B$10) -> 1.2164249e+08
A14: Teaching Materials & Curriculum Licensing | B14: =Assumptions!$B$47*12 -> 60000000 | C14: =B14*(1+Assumptions!$B$10) -> 63600000 | D14: =C14*(1+Assumptions!$B$10) -> 67416000 | E14: =D14*(1+Assumptions!$B$10) -> 71460960 | F14: =E14*(1+Assumptions!$B$10) -> 75748618 | G14: =F14*(1+Assumptions!$B$10) -> 80293535 | H14: =G14*(1+Assumptions!$B$10) -> 85111147 | I14: =H14*(1+Assumptions!$B$10) -> 90217816 | J14: =I14*(1+Assumptions!$B$10) -> 95630884 | K14: =J14*(1+Assumptions!$B$10) -> 1.0136874e+08
A15: Marketing & Admissions | B15: =Assumptions!$B$48*12 -> 48000000 | C15: =B15*(1+Assumptions!$B$10) -> 50880000 | D15: =C15*(1+Assumptions!$B$10) -> 53932800 | E15: =D15*(1+Assumptions!$B$10) -> 57168768 | F15: =E15*(1+Assumptions!$B$10) -> 60598894 | G15: =F15*(1+Assumptions!$B$10) -> 64234828 | H15: =G15*(1+Assumptions!$B$10) -> 68088917 | I15: =H15*(1+Assumptions!$B$10) -> 72174252 | J15: =I15*(1+Assumptions!$B$10) -> 76504708 | K15: =J15*(1+Assumptions!$B$10) -> 81094990
A16: Licensing, Permits & Insurance | B16: =Assumptions!$B$49*12 -> 36000000 | C16: =B16*(1+Assumptions!$B$10) -> 38160000 | D16: =C16*(1+Assumptions!$B$10) -> 40449600 | E16: =D16*(1+Assumptions!$B$10) -> 42876576 | F16: =E16*(1+Assumptions!$B$10) -> 45449171 | G16: =F16*(1+Assumptions!$B$10) -> 48176121 | H16: =G16*(1+Assumptions!$B$10) -> 51066688 | I16: =H16*(1+Assumptions!$B$10) -> 54130689 | J16: =I16*(1+Assumptions!$B$10) -> 57378531 | K16: =J16*(1+Assumptions!$B$10) -> 60821243
A17: Maintenance & Miscellaneous | B17: =Assumptions!$B$50*12 -> 36000000 | C17: =B17*(1+Assumptions!$B$10) -> 38160000 | D17: =C17*(1+Assumptions!$B$10) -> 40449600 | E17: =D17*(1+Assumptions!$B$10) -> 42876576 | F17: =E17*(1+Assumptions!$B$10) -> 45449171 | G17: =F17*(1+Assumptions!$B$10) -> 48176121 | H17: =G17*(1+Assumptions!$B$10) -> 51066688 | I17: =H17*(1+Assumptions!$B$10) -> 54130689 | J17: =I17*(1+Assumptions!$B$10) -> 57378531 | K17: =J17*(1+Assumptions!$B$10) -> 60821243
A18: Depreciation (Rp0 after Year 5 — fully depreciated) | B18: =IF(1<=Assumptions!$B$58,Assumptions!$B$59,0) -> 130000000 | C18: =IF(2<=Assumptions!$B$58,Assumptions!$B$59,0) -> 130000000 | D18: =IF(3<=Assumptions!$B$58,Assumptions!$B$59,0) -> 130000000 | E18: =IF(4<=Assumptions!$B$58,Assumptions!$B$59,0) -> 130000000 | F18: =IF(5<=Assumptions!$B$58,Assumptions!$B$59,0) -> 130000000 | G18: =IF(6<=Assumptions!$B$58,Assumptions!$B$59,0) -> 0 | H18: =IF(7<=Assumptions!$B$58,Assumptions!$B$59,0) -> 0 | I18: =IF(8<=Assumptions!$B$58,Assumptions!$B$59,0) -> 0 | J18: =IF(9<=Assumptions!$B$58,Assumptions!$B$59,0) -> 0 | K18: =IF(10<=Assumptions!$B$58,Assumptions!$B$59,0) -> 0
A19: Total Operating Expenses | B19: =B11+B12+B13+B14+B15+B16+B17+B18 -> 2329000000 | C19: =C11+C12+C13+C14+C15+C16+C17+C18 -> 2460940000 | D19: =D11+D12+D13+D14+D15+D16+D17+D18 -> 2600796400 | E19: =E11+E12+E13+E14+E15+E16+E17+E18 -> 2749044184 | F19: =F11+F12+F13+F14+F15+F16+F17+F18 -> 2.9061868e+09 | G19: =G11+G12+G13+G14+G15+G16+G17+G18 -> 2.942758e+09 | H19: =H11+H12+H13+H14+H15+H16+H17+H18 -> 3.1193235e+09 | I19: =I11+I12+I13+I14+I15+I16+I17+I18 -> 3.3064829e+09 | ... K19: =K11+K12+K13+K14+K15+K16+K17+K18 -> 3.7151642e+09
A21: EBIT (Operating Profit) | B21: =B8-B19 -> -849287500 | C21: =C8-C19 -> 1.0044234e+08 | D21: =D8-D19 -> 9.170061e+08 | E21: =E8-E19 -> 2.0823058e+09 | F21: =F8-F19 -> 3.7291892e+09 | G21: =G8-G19 -> 6.1702674e+09 | H21: =H8-H19 -> 9.3854661e+09 | I21: =I8-I19 -> 1.1565689e+10 | ... K21: =K8-K19 -> 1.2681405e+10
A22: Corporate Income Tax | B22: =MAX(B21,0)*Assumptions!$B$9 -> 0 | C22: =MAX(C21,0)*Assumptions!$B$9 -> 22097314 | D22: =MAX(D21,0)*Assumptions!$B$9 -> 2.0174134e+08 | E22: =MAX(E21,0)*Assumptions!$B$9 -> 4.5810727e+08 | F22: =MAX(F21,0)*Assumptions!$B$9 -> 8.2042162e+08 | G22: =MAX(G21,0)*Assumptions!$B$9 -> 1.3574588e+09 | H22: =MAX(H21,0)*Assumptions!$B$9 -> 2.0648025e+09 | I22: =MAX(I21,0)*Assumptions!$B$9 -> 2.5444516e+09 | ... K22: =MAX(K21,0)*Assumptions!$B$9 -> 2.7899092e+09
A23: Net Income | B23: =B21-B22 -> -849287500 | C23: =C21-C22 -> 78345023 | D23: =D21-D22 -> 7.1526476e+08 | E23: =E21-E22 -> 1.6241985e+09 | F23: =F21-F22 -> 2.9087676e+09 | G23: =G21-G22 -> 4.8128086e+09 | H23: =H21-H22 -> 7.3206635e+09 | I23: =I21-I22 -> 9.0212375e+09 | ... K23: =K21-K22 -> 9.8914962e+09
A24: Net Margin (%) | B24: =B23/B8 -> -0.5739544 | C24: =C23/C8 -> 0.030587008 | D24: =D23/D8 -> 0.20332715 | E24: =E23/E8 -> 0.33617902 | F24: =F23/F8 -> 0.43837268 | G24: =G23/G8 -> 0.52812412 | H24: =H23/H8 -> 0.58542877 | I24: =I23/I8 -> 0.60658507 | ... K24: =K23/K8 -> 0.6032662
A26: ="Note: Year 0 one-time startup capex (see Assumptions tab) is invested before Year 1 operations begin and is not repeated in this P&L; it is depreciated straight-line over Years 1–5, then fully depreciated (Rp0 charge) in Years 6–10." -> Note: Year 0 one-time startup capex (see Assumptions tab) is invested before Year 1 operations begin and is not repeated in this P&L; it is depreciated straight-line over Years 1–5, then fully depreciated (Rp0 charge) in Years 6–10.
